Loaded from file system
[2023-02-09 01:46:45.097079] Epoch[0/1], Step[49/81], D_losses: [0.006952980533242226|0.2216949462890625|0.3702523410320282|0.10381542146205902], G_losses:[0.6265339851379395|0.04212880879640579]
Traceback (most recent call last):
  File "Trainer.py", line 225, in <module>
    trainer.train()
  File "Trainer.py", line 146, in train
    for i, data in enumerate(self.data_loader):
  File "/Users/garipovroma/anaconda3/envs/diploma/lib/python3.8/site-packages/torch/utils/data/dataloader.py", line 635, in __next__
    data = self._next_data()
  File "/Users/garipovroma/anaconda3/envs/diploma/lib/python3.8/site-packages/torch/utils/data/dataloader.py", line 1347, in _next_data
    return self._process_data(data)
  File "/Users/garipovroma/anaconda3/envs/diploma/lib/python3.8/site-packages/torch/utils/data/dataloader.py", line 1373, in _process_data
    data.reraise()
  File "/Users/garipovroma/anaconda3/envs/diploma/lib/python3.8/site-packages/torch/_utils.py", line 636, in reraise
    raise exception
RuntimeError: Caught RuntimeError in DataLoader worker process 3.
Original Traceback (most recent call last):
  File "/Users/garipovroma/anaconda3/envs/diploma/lib/python3.8/site-packages/torch/utils/data/_utils/worker.py", line 308, in _worker_loop
    data = fetcher.fetch(index)
  File "/Users/garipovroma/anaconda3/envs/diploma/lib/python3.8/site-packages/torch/utils/data/_utils/fetch.py", line 58, in fetch
    data = [self.dataset[idx] for idx in possibly_batched_index]
  File "/Users/garipovroma/anaconda3/envs/diploma/lib/python3.8/site-packages/torch/utils/data/_utils/fetch.py", line 58, in <listcomp>
    data = [self.dataset[idx] for idx in possibly_batched_index]
  File "/Users/garipovroma/work/itmo/diploma/MetaLearning-GAN/meta_gan/DatasetLoader.py", line 32, in __getitem__
    dataset_tensor = torch.from_numpy(data_np).float().view((self.classes, self.instances, self.features))
RuntimeError: shape '[2, 64, 16]' is invalid for input of size 216000
