Loaded from file system
[2023-02-22 22:44:44.745031] Epoch[0/1], Step[49/81], D_losses: [0.09834817796945572|0.26759472489356995|0.650002658367157|0.20802919566631317], G_losses:[0.066260427236557|0.05746748670935631]
Traceback (most recent call last):
  File "/Users/garipovroma/work/itmo/diploma/MetaLearning-GAN/meta_gan/Trainer.py", line 225, in <module>
    trainer.train()
  File "/Users/garipovroma/work/itmo/diploma/MetaLearning-GAN/meta_gan/Trainer.py", line 146, in train
    for i, data in enumerate(self.data_loader):
  File "/Users/garipovroma/anaconda3/envs/diploma/lib/python3.8/site-packages/torch/utils/data/dataloader.py", line 635, in __next__
    data = self._next_data()
  File "/Users/garipovroma/anaconda3/envs/diploma/lib/python3.8/site-packages/torch/utils/data/dataloader.py", line 1347, in _next_data
    return self._process_data(data)
  File "/Users/garipovroma/anaconda3/envs/diploma/lib/python3.8/site-packages/torch/utils/data/dataloader.py", line 1373, in _process_data
    data.reraise()
  File "/Users/garipovroma/anaconda3/envs/diploma/lib/python3.8/site-packages/torch/_utils.py", line 636, in reraise
    raise exception
RuntimeError: Caught RuntimeError in DataLoader worker process 1.
Original Traceback (most recent call last):
  File "/Users/garipovroma/anaconda3/envs/diploma/lib/python3.8/site-packages/torch/utils/data/_utils/worker.py", line 308, in _worker_loop
    data = fetcher.fetch(index)
  File "/Users/garipovroma/anaconda3/envs/diploma/lib/python3.8/site-packages/torch/utils/data/_utils/fetch.py", line 58, in fetch
    data = [self.dataset[idx] for idx in possibly_batched_index]
  File "/Users/garipovroma/anaconda3/envs/diploma/lib/python3.8/site-packages/torch/utils/data/_utils/fetch.py", line 58, in <listcomp>
    data = [self.dataset[idx] for idx in possibly_batched_index]
  File "/Users/garipovroma/work/itmo/diploma/MetaLearning-GAN/meta_gan/DatasetLoader.py", line 32, in __getitem__
    dataset_tensor = torch.from_numpy(data_np).float().view((self.classes, self.instances, self.features))
RuntimeError: shape '[2, 64, 16]' is invalid for input of size 216000


Process finished with exit code 1

